Mini-batch information for training not found. Generating..
0 / 20
1 / 20
2 / 20
3 / 20
4 / 20
5 / 20
6 / 20
7 / 20
8 / 20
9 / 20
10 / 20
11 / 20
12 / 20
13 / 20
14 / 20
15 / 20
16 / 20
17 / 20
18 / 20
19 / 20
Mini-batch information for validation not found. Generating..
0 / 8
1 / 8
2 / 8
3 / 8
4 / 8
5 / 8
6 / 8
7 / 8
CONFIGURATION:
           base: dynedge-E-protov2-azimuth 
           n_reps: 1 
           batch_size: 2048 
           learning rate: 7.0e-04 
           max_lr: 2.5e-03 
           end_lr: 7.0e-04 
           n_epochs: 50 
           patience: 5 
           scheduler: LinearSchedule 
           steps_up: 2400.0 
           steps_down: 21600.0 
TRAINING BEGUN. FIRST EPOCH STARTING..
[W python_anomaly_mode.cpp:104] Warning: Error detected in AddmmBackward. Traceback of forward call that caused the error:
  File "dynedge_likelihood_azimuth_pair_protov2.py", line 650, in <module>
    trained_model,loss_history = Train(Net(),graphs_train,device,lr,lr_list,n_workers,batch_size,loss_decimals,graphs_valid,mini_batches_valid)
  File "dynedge_likelihood_azimuth_pair_protov2.py", line 387, in Train
    out                         = model(data_train)
  File "/groups/hep/pcs557/anaconda3/lib/python3.8/site-packages/torch/nn/modules/module.py", line 727, in _call_impl
    result = self.forward(*input, **kwargs)
  File "dynedge_likelihood_azimuth_pair_protov2.py", line 239, in forward
    d = self.conv_add4(c,edge_index)
  File "/groups/hep/pcs557/anaconda3/lib/python3.8/site-packages/torch/nn/modules/module.py", line 727, in _call_impl
    result = self.forward(*input, **kwargs)
  File "/groups/hep/pcs557/anaconda3/lib/python3.8/site-packages/torch_geometric/nn/conv/edge_conv.py", line 51, in forward
    return self.propagate(edge_index, x=x, size=None)
  File "/groups/hep/pcs557/anaconda3/lib/python3.8/site-packages/torch_geometric/nn/conv/message_passing.py", line 237, in propagate
    out = self.message(**msg_kwargs)
  File "/groups/hep/pcs557/anaconda3/lib/python3.8/site-packages/torch_geometric/nn/conv/edge_conv.py", line 54, in message
    return self.nn(torch.cat([x_i, x_j - x_i], dim=-1))
  File "/groups/hep/pcs557/anaconda3/lib/python3.8/site-packages/torch/nn/modules/module.py", line 727, in _call_impl
    result = self.forward(*input, **kwargs)
  File "/groups/hep/pcs557/anaconda3/lib/python3.8/site-packages/torch/nn/modules/container.py", line 117, in forward
    input = module(input)
  File "/groups/hep/pcs557/anaconda3/lib/python3.8/site-packages/torch/nn/modules/module.py", line 727, in _call_impl
    result = self.forward(*input, **kwargs)
  File "/groups/hep/pcs557/anaconda3/lib/python3.8/site-packages/torch/nn/modules/linear.py", line 93, in forward
    return F.linear(input, self.weight, self.bias)
  File "/groups/hep/pcs557/anaconda3/lib/python3.8/site-packages/torch/nn/functional.py", line 1690, in linear
    ret = torch.addmm(bias, input, weight.t())
 (function _print_stack)
All task requests sent
Traceback (most recent call last):
  File "dynedge_likelihood_azimuth_pair_protov2.py", line 650, in <module>
    trained_model,loss_history = Train(Net(),graphs_train,device,lr,lr_list,n_workers,batch_size,loss_decimals,graphs_valid,mini_batches_valid)
  File "dynedge_likelihood_azimuth_pair_protov2.py", line 393, in Train
    loss.backward()                                                         
  File "/groups/hep/pcs557/anaconda3/lib/python3.8/site-packages/torch/tensor.py", line 221, in backward
    torch.autograd.backward(self, gradient, retain_graph, create_graph)
  File "/groups/hep/pcs557/anaconda3/lib/python3.8/site-packages/torch/autograd/__init__.py", line 130, in backward
    Variable._execution_engine.run_backward(
RuntimeError: CUDA out of memory. Tried to allocate 1.10 GiB (GPU 1; 23.70 GiB total capacity; 16.74 GiB already allocated; 807.31 MiB free; 21.53 GiB reserved in total by PyTorch)
Process Process-10:
Traceback (most recent call last):
  File "/groups/hep/pcs557/anaconda3/lib/python3.8/multiprocessing/process.py", line 315, in _bootstrap
    self.run()
  File "/groups/hep/pcs557/anaconda3/lib/python3.8/multiprocessing/process.py", line 108, in run
    self._target(*self._args, **self._kwargs)
  File "dynedge_likelihood_azimuth_pair_protov2.py", line 276, in worker
    q.put(next(loader_it))
  File "<string>", line 2, in put
  File "/groups/hep/pcs557/anaconda3/lib/python3.8/multiprocessing/managers.py", line 835, in _callmethod
    kind, result = conn.recv()
  File "/groups/hep/pcs557/anaconda3/lib/python3.8/multiprocessing/connection.py", line 250, in recv
    buf = self._recv_bytes()
  File "/groups/hep/pcs557/anaconda3/lib/python3.8/multiprocessing/connection.py", line 414, in _recv_bytes
    buf = self._recv(4)
  File "/groups/hep/pcs557/anaconda3/lib/python3.8/multiprocessing/connection.py", line 379, in _recv
    chunk = read(handle, remaining)
ConnectionResetError: [Errno 104] Connection reset by peer
Process Process-9:
Traceback (most recent call last):
  File "/groups/hep/pcs557/anaconda3/lib/python3.8/multiprocessing/process.py", line 315, in _bootstrap
    self.run()
  File "/groups/hep/pcs557/anaconda3/lib/python3.8/multiprocessing/process.py", line 108, in run
    self._target(*self._args, **self._kwargs)
  File "dynedge_likelihood_azimuth_pair_protov2.py", line 276, in worker
    q.put(next(loader_it))
  File "<string>", line 2, in put
  File "/groups/hep/pcs557/anaconda3/lib/python3.8/multiprocessing/managers.py", line 835, in _callmethod
    kind, result = conn.recv()
  File "/groups/hep/pcs557/anaconda3/lib/python3.8/multiprocessing/connection.py", line 250, in recv
    buf = self._recv_bytes()
  File "/groups/hep/pcs557/anaconda3/lib/python3.8/multiprocessing/connection.py", line 414, in _recv_bytes
    buf = self._recv(4)
  File "/groups/hep/pcs557/anaconda3/lib/python3.8/multiprocessing/connection.py", line 379, in _recv
    chunk = read(handle, remaining)
ConnectionResetError: [Errno 104] Connection reset by peer
Process Process-11:
Traceback (most recent call last):
  File "/groups/hep/pcs557/anaconda3/lib/python3.8/multiprocessing/process.py", line 315, in _bootstrap
    self.run()
  File "/groups/hep/pcs557/anaconda3/lib/python3.8/multiprocessing/process.py", line 108, in run
    self._target(*self._args, **self._kwargs)
  File "dynedge_likelihood_azimuth_pair_protov2.py", line 276, in worker
    q.put(next(loader_it))
  File "<string>", line 2, in put
  File "/groups/hep/pcs557/anaconda3/lib/python3.8/multiprocessing/managers.py", line 834, in _callmethod
    conn.send((self._id, methodname, args, kwds))
  File "/groups/hep/pcs557/anaconda3/lib/python3.8/multiprocessing/connection.py", line 206, in send
    self._send_bytes(_ForkingPickler.dumps(obj))
  File "/groups/hep/pcs557/anaconda3/lib/python3.8/multiprocessing/connection.py", line 404, in _send_bytes
    self._send(header)
  File "/groups/hep/pcs557/anaconda3/lib/python3.8/multiprocessing/connection.py", line 368, in _send
    n = write(self._handle, buf)
BrokenPipeError: [Errno 32] Broken pipe
Process Process-5:
Traceback (most recent call last):
  File "/groups/hep/pcs557/anaconda3/lib/python3.8/multiprocessing/process.py", line 315, in _bootstrap
    self.run()
  File "/groups/hep/pcs557/anaconda3/lib/python3.8/multiprocessing/process.py", line 108, in run
    self._target(*self._args, **self._kwargs)
  File "dynedge_likelihood_azimuth_pair_protov2.py", line 276, in worker
    q.put(next(loader_it))
  File "<string>", line 2, in put
  File "/groups/hep/pcs557/anaconda3/lib/python3.8/multiprocessing/managers.py", line 834, in _callmethod
    conn.send((self._id, methodname, args, kwds))
  File "/groups/hep/pcs557/anaconda3/lib/python3.8/multiprocessing/connection.py", line 206, in send
    self._send_bytes(_ForkingPickler.dumps(obj))
  File "/groups/hep/pcs557/anaconda3/lib/python3.8/multiprocessing/connection.py", line 404, in _send_bytes
    self._send(header)
  File "/groups/hep/pcs557/anaconda3/lib/python3.8/multiprocessing/connection.py", line 368, in _send
    n = write(self._handle, buf)
BrokenPipeError: [Errno 32] Broken pipe
Process Process-7:
Traceback (most recent call last):
  File "/groups/hep/pcs557/anaconda3/lib/python3.8/multiprocessing/process.py", line 315, in _bootstrap
    self.run()
  File "/groups/hep/pcs557/anaconda3/lib/python3.8/multiprocessing/process.py", line 108, in run
    self._target(*self._args, **self._kwargs)
  File "dynedge_likelihood_azimuth_pair_protov2.py", line 276, in worker
    q.put(next(loader_it))
  File "<string>", line 2, in put
  File "/groups/hep/pcs557/anaconda3/lib/python3.8/multiprocessing/managers.py", line 834, in _callmethod
    conn.send((self._id, methodname, args, kwds))
  File "/groups/hep/pcs557/anaconda3/lib/python3.8/multiprocessing/connection.py", line 206, in send
    self._send_bytes(_ForkingPickler.dumps(obj))
  File "/groups/hep/pcs557/anaconda3/lib/python3.8/multiprocessing/connection.py", line 404, in _send_bytes
    self._send(header)
  File "/groups/hep/pcs557/anaconda3/lib/python3.8/multiprocessing/connection.py", line 368, in _send
    n = write(self._handle, buf)
BrokenPipeError: [Errno 32] Broken pipe
Process Process-2:
Traceback (most recent call last):
  File "/groups/hep/pcs557/anaconda3/lib/python3.8/multiprocessing/process.py", line 315, in _bootstrap
    self.run()
  File "/groups/hep/pcs557/anaconda3/lib/python3.8/multiprocessing/process.py", line 108, in run
    self._target(*self._args, **self._kwargs)
  File "dynedge_likelihood_azimuth_pair_protov2.py", line 276, in worker
    q.put(next(loader_it))
  File "<string>", line 2, in put
  File "/groups/hep/pcs557/anaconda3/lib/python3.8/multiprocessing/managers.py", line 834, in _callmethod
    conn.send((self._id, methodname, args, kwds))
  File "/groups/hep/pcs557/anaconda3/lib/python3.8/multiprocessing/connection.py", line 206, in send
    self._send_bytes(_ForkingPickler.dumps(obj))
  File "/groups/hep/pcs557/anaconda3/lib/python3.8/multiprocessing/connection.py", line 404, in _send_bytes
    self._send(header)
  File "/groups/hep/pcs557/anaconda3/lib/python3.8/multiprocessing/connection.py", line 368, in _send
    n = write(self._handle, buf)
BrokenPipeError: [Errno 32] Broken pipe
Process Process-3:
Traceback (most recent call last):
  File "/groups/hep/pcs557/anaconda3/lib/python3.8/multiprocessing/process.py", line 315, in _bootstrap
    self.run()
  File "/groups/hep/pcs557/anaconda3/lib/python3.8/multiprocessing/process.py", line 108, in run
    self._target(*self._args, **self._kwargs)
  File "dynedge_likelihood_azimuth_pair_protov2.py", line 276, in worker
    q.put(next(loader_it))
  File "<string>", line 2, in put
  File "/groups/hep/pcs557/anaconda3/lib/python3.8/multiprocessing/managers.py", line 834, in _callmethod
    conn.send((self._id, methodname, args, kwds))
  File "/groups/hep/pcs557/anaconda3/lib/python3.8/multiprocessing/connection.py", line 206, in send
    self._send_bytes(_ForkingPickler.dumps(obj))
  File "/groups/hep/pcs557/anaconda3/lib/python3.8/multiprocessing/connection.py", line 404, in _send_bytes
    self._send(header)
  File "/groups/hep/pcs557/anaconda3/lib/python3.8/multiprocessing/connection.py", line 368, in _send
    n = write(self._handle, buf)
BrokenPipeError: [Errno 32] Broken pipe
Process Process-6:
Traceback (most recent call last):
  File "/groups/hep/pcs557/anaconda3/lib/python3.8/multiprocessing/process.py", line 315, in _bootstrap
    self.run()
  File "/groups/hep/pcs557/anaconda3/lib/python3.8/multiprocessing/process.py", line 108, in run
    self._target(*self._args, **self._kwargs)
  File "dynedge_likelihood_azimuth_pair_protov2.py", line 276, in worker
    q.put(next(loader_it))
  File "<string>", line 2, in put
  File "/groups/hep/pcs557/anaconda3/lib/python3.8/multiprocessing/managers.py", line 834, in _callmethod
    conn.send((self._id, methodname, args, kwds))
  File "/groups/hep/pcs557/anaconda3/lib/python3.8/multiprocessing/connection.py", line 206, in send
    self._send_bytes(_ForkingPickler.dumps(obj))
  File "/groups/hep/pcs557/anaconda3/lib/python3.8/multiprocessing/connection.py", line 404, in _send_bytes
    self._send(header)
  File "/groups/hep/pcs557/anaconda3/lib/python3.8/multiprocessing/connection.py", line 368, in _send
    n = write(self._handle, buf)
BrokenPipeError: [Errno 32] Broken pipe
Process Process-8:
Traceback (most recent call last):
  File "/groups/hep/pcs557/anaconda3/lib/python3.8/multiprocessing/process.py", line 315, in _bootstrap
    self.run()
  File "/groups/hep/pcs557/anaconda3/lib/python3.8/multiprocessing/process.py", line 108, in run
    self._target(*self._args, **self._kwargs)
  File "dynedge_likelihood_azimuth_pair_protov2.py", line 276, in worker
    q.put(next(loader_it))
  File "<string>", line 2, in put
  File "/groups/hep/pcs557/anaconda3/lib/python3.8/multiprocessing/managers.py", line 834, in _callmethod
    conn.send((self._id, methodname, args, kwds))
  File "/groups/hep/pcs557/anaconda3/lib/python3.8/multiprocessing/connection.py", line 206, in send
    self._send_bytes(_ForkingPickler.dumps(obj))
  File "/groups/hep/pcs557/anaconda3/lib/python3.8/multiprocessing/connection.py", line 404, in _send_bytes
    self._send(header)
  File "/groups/hep/pcs557/anaconda3/lib/python3.8/multiprocessing/connection.py", line 368, in _send
    n = write(self._handle, buf)
BrokenPipeError: [Errno 32] Broken pipe
Process Process-4:
Traceback (most recent call last):
  File "/groups/hep/pcs557/anaconda3/lib/python3.8/multiprocessing/process.py", line 315, in _bootstrap
    self.run()
  File "/groups/hep/pcs557/anaconda3/lib/python3.8/multiprocessing/process.py", line 108, in run
    self._target(*self._args, **self._kwargs)
  File "dynedge_likelihood_azimuth_pair_protov2.py", line 276, in worker
    q.put(next(loader_it))
  File "<string>", line 2, in put
  File "/groups/hep/pcs557/anaconda3/lib/python3.8/multiprocessing/managers.py", line 834, in _callmethod
    conn.send((self._id, methodname, args, kwds))
  File "/groups/hep/pcs557/anaconda3/lib/python3.8/multiprocessing/connection.py", line 206, in send
    self._send_bytes(_ForkingPickler.dumps(obj))
  File "/groups/hep/pcs557/anaconda3/lib/python3.8/multiprocessing/connection.py", line 404, in _send_bytes
    self._send(header)
  File "/groups/hep/pcs557/anaconda3/lib/python3.8/multiprocessing/connection.py", line 368, in _send
    n = write(self._handle, buf)
BrokenPipeError: [Errno 32] Broken pipe
